<?xml version="1.0" ?>
<!-- =================================================================================== -->
<!-- |    This document was autogenerated by xacro from /home/lawkaho/workshop/zlab_robots/catkin_ws/src/frcobot_description/urdf/fr5v6_single_arm.xacro | -->
<!-- |    EDITING THIS FILE BY HAND IS NOT RECOMMENDED                                 | -->
<!-- =================================================================================== -->
<robot name="fr5v6_single_arm">
    <!-- 添加虚拟根链接 -->
    <link name="world" />
    <joint name="fr5v6_joint_base" type="fixed">
        <parent link="world" />
        <child link="fr5v6_extra_base_link" />
        <origin rpy="0 0 0" xyz="0 0 0" />
    </joint>
    <link name="fr5v6_extra_base_link">
        <inertial>
            <origin rpy="0 0 0" xyz="-0.00035477 0.0011738 0.038422" />
            <mass value="6.8715" />
            <inertia ixx="0.11261" ixy="-2.8693e-05" ixz="-0.0017586" iyy="0.11265" iyz="0.002588" izz="0.19704" />
        </inertial>
        <visual>
            <origin rpy="0 0 0" xyz="0 0 0" />
            <geometry>
                <mesh filename="package://frcobot_description/meshes/fr5v6/visual/extra_base_link.DAE" scale="1 1 1" />
            </geometry>
            <material name="">
                <color rgba="0.89804 0.91765 0.92941 1" />
            </material>
        </visual>
        <collision>
            <origin rpy="0 0 0" xyz="0 0 0" />
            <geometry>
                <mesh filename="package://frcobot_description/meshes/fr5v6/collision/extra_base_link.STL" scale="1 1 1" />
            </geometry>
        </collision>
    </link>
    <joint name="fr5v6_extra_base_to_plant" type="fixed">
        <parent link="fr5v6_extra_base_link" />
        <child link="fr5v6_plant_link" />
        <origin rpy="0 0 0" xyz="-0.00031408 0.00046097 0.41799" />
    </joint>
    <link name="fr5v6_plant_link">
        <inertial>
            <origin rpy="0 0 0" xyz="2.7756E-16 0 -0.008" />
            <mass value="0.40503" />
            <inertia ixx="0.0008273" ixy="-2.5374e-19" ixz="1.6905e-22" iyy="0.0008273" iyz="-2.1817e-22" izz="0.0016373" />
        </inertial>
        <visual>
            <origin rpy="0 0 0" xyz="0 0 0" />
            <geometry>
                <mesh filename="package://frcobot_description/meshes/fr5v6/visual/plant_link.DAE" scale="1 1 1" />
            </geometry>
            <material name="">
                <color rgba="0.89804 0.91765 0.92941 1" />
            </material>
        </visual>
        <collision>
            <origin rpy="0 0 0" xyz="0 0 0" />
            <geometry>
                <mesh filename="package://frcobot_description/meshes/fr5v6/collision/plant_link.STL" scale="1 1 1" />
            </geometry>
        </collision>
    </link>
    <joint name="fr5v6_extra_plant_to_base" type="fixed">
        <parent link="fr5v6_plant_link" />
        <child link="fr5v6_base_link" />
        <origin rpy="0 0 0" xyz="0 0 0.0001" />
    </joint>
    <link name="fr5v6_base_link">
        <inertial>
            <origin rpy="0 0 0" xyz="-0.00031896 -0.00029673 0.042463" />
            <mass value="1.6185" />
            <inertia ixx="0.0030836" ixy="1.5354e-05" ixz="-1.9315e-05" iyy="0.0030825" iyz="-1.7918e-05" izz="0.0045209" />
        </inertial>
        <visual>
            <origin rpy="0 0 0" xyz="0 0 0" />
            <geometry>
                <mesh filename="package://frcobot_description/meshes/fr5v6/visual/base_link.DAE" scale="1 1 1" />
            </geometry>
            <material name="">
                <color rgba="0.89804 0.91765 0.92941 1" />
            </material>
        </visual>
        <collision>
            <origin rpy="0 0 0" xyz="0 0 0" />
            <geometry>
                <mesh filename="package://frcobot_description/meshes/fr5v6/collision/base_link.STL" scale="1 1 1" />
            </geometry>
        </collision>
    </link>
    <link name="fr5v6_j1_link">
        <inertial>
            <origin rpy="0 0 0" xyz="5.0029E-07 -0.0040922 0.14629" />
            <mass value="4.3771" />
            <inertia ixx="0.010731" ixy="-8.0587e-09" ixz="-3.6773e-08" iyy="0.010408" iyz="0.00012853" izz="0.0081793" />
        </inertial>
        <visual>
            <origin rpy="0 0 0" xyz="0 0 0" />
            <geometry>
                <mesh filename="package://frcobot_description/meshes/fr5v6/visual/j1_link.DAE" scale="1 1 1" />
            </geometry>
            <material name="">
                <color rgba="0.89804 0.91765 0.92941 1" />
            </material>
        </visual>
        <collision>
            <origin rpy="0 0 0" xyz="0 0 0" />
            <geometry>
                <mesh filename="package://frcobot_description/meshes/fr5v6/collision/j1_link.STL" scale="1 1 1" />
            </geometry>
        </collision>
    </link>
    <joint name="fr5v6_j1" type="revolute">
        <origin rpy="0 0 0" xyz="0 0 0" />
        <parent link="fr5v6_base_link" />
        <child link="fr5v6_j1_link" />
        <axis xyz="0 0 1" />
        <limit effort="150" lower="-3.0543" upper="3.0543" velocity="3.15" />
        <calibration falling="0" rising="0" />
        <dynamics damping="0" friction="0" />
        <safety_controller k_position="15" k_velocity="10" soft_lower_limit="-3.0543" soft_upper_limit="3.0543" />
    </joint>
    <link name="fr5v6_j2_link">
        <inertial>
            <origin rpy="0 0 0" xyz="-0.2125 -5.7643E-09 0.1346" />
            <mass value="14.458" />
            <inertia ixx="0.028392" ixy="-1.337e-07" ixz="-3.9895e-09" iyy="0.4559" iyz="4.214e-08" izz="0.44974" />
        </inertial>
        <visual>
            <origin rpy="0 0 0" xyz="0 0 0" />
            <geometry>
                <mesh filename="package://frcobot_description/meshes/fr5v6/visual/j2_link.DAE" scale="1 1 1" />
            </geometry>
            <material name="">
                <color rgba="0.89804 0.91765 0.92941 1" />
            </material>
        </visual>
        <collision>
            <origin rpy="0 0 0" xyz="0 0 0" />
            <geometry>
                <mesh filename="package://frcobot_description/meshes/fr5v6/collision/j2_link.STL" scale="1 1 1" />
            </geometry>
        </collision>
    </link>
    <joint name="fr5v6_j2" type="revolute">
        <origin rpy="1.5708 0 0" xyz="0 0 0.152" />
        <parent link="fr5v6_j1_link" />
        <child link="fr5v6_j2_link" />
        <axis xyz="0 0 1" />
        <limit effort="150" lower="-4.6251" upper="1.4835" velocity="3.15" />
        <calibration falling="0" rising="0" />
        <dynamics damping="0" friction="0" />
        <safety_controller k_position="15" k_velocity="10" soft_lower_limit="-4.6251" soft_upper_limit="1.4835" />
    </joint>
    <link name="fr5v6_j3_link">
        <inertial>
            <origin rpy="0 0 0" xyz="-0.18793 -8.4503E-07 0.0066357" />
            <mass value="7.6737" />
            <inertia ixx="0.0085096" ixy="2.1613e-06" ixz="-0.0068678" iyy="0.16971" iyz="3.7086e-08" izz="0.16854" />
        </inertial>
        <visual>
            <origin rpy="0 0 0" xyz="0 0 0" />
            <geometry>
                <mesh filename="package://frcobot_description/meshes/fr5v6/visual/j3_link.DAE" scale="1 1 1" />
            </geometry>
            <material name="">
                <color rgba="0.89804 0.91765 0.92941 1" />
            </material>
        </visual>
        <collision>
            <origin rpy="0 0 0" xyz="0 0 0" />
            <geometry>
                <mesh filename="package://frcobot_description/meshes/fr5v6/collision/j3_link.STL" scale="1 1 1" />
            </geometry>
        </collision>
    </link>
    <joint name="fr5v6_j3" type="revolute">
        <origin rpy="0 0 0" xyz="-0.425 0 0" />
        <parent link="fr5v6_j2_link" />
        <child link="fr5v6_j3_link" />
        <axis xyz="0 0 1" />
        <limit effort="150" lower="-2.8274" upper="2.8274" velocity="3.15" />
        <calibration falling="0" rising="0" />
        <dynamics damping="0" friction="0" />
        <safety_controller k_position="15" k_velocity="10" soft_lower_limit="-2.8274" soft_upper_limit="2.8274" />
    </joint>
    <link name="fr5v6_j4_link">
        <inertial>
            <origin rpy="0 0 0" xyz="4.98E-07 -0.003754 0.097155" />
            <mass value="1.6266" />
            <inertia ixx="0.00216" ixy="4.888e-09" ixz="3.1528e-08" iyy="0.0015455" iyz="3.7678e-05" izz="0.0019902" />
        </inertial>
        <visual>
            <origin rpy="0 0 0" xyz="0 0 0" />
            <geometry>
                <mesh filename="package://frcobot_description/meshes/fr5v6/visual/j4_link.DAE" scale="1 1 1" />
            </geometry>
            <material name="">
                <color rgba="0.89804 0.91765 0.92941 1" />
            </material>
        </visual>
        <collision>
            <origin rpy="0 0 0" xyz="0 0 0" />
            <geometry>
                <mesh filename="package://frcobot_description/meshes/fr5v6/collision/j4_link.STL" scale="1 1 1" />
            </geometry>
        </collision>
    </link>
    <joint name="fr5v6_j4" type="revolute">
        <origin rpy="0 0 0" xyz="-0.39501 0 0" />
        <parent link="fr5v6_j3_link" />
        <child link="fr5v6_j4_link" />
        <axis xyz="0 0 1" />
        <limit effort="28" lower="-4.6251" upper="1.4835" velocity="3.2" />
        <calibration falling="0" rising="0" />
        <dynamics damping="0" friction="0" />
        <safety_controller k_position="15" k_velocity="10" soft_lower_limit="-4.6251" soft_upper_limit="1.4835" />
    </joint>
    <link name="fr5v6_j5_link">
        <inertial>
            <origin rpy="0 0 0" xyz="-4.5588E-07 0.0038617 0.098257" />
            <mass value="1.5812" />
            <inertia ixx="0.0020612" ixy="8.7064e-09" ixz="-3.4742e-08" iyy="0.0014477" iyz="-2.8534e-05" izz="0.0019573" />
        </inertial>
        <visual>
            <origin rpy="0 0 0" xyz="0 0 0" />
            <geometry>
                <mesh filename="package://frcobot_description/meshes/fr5v6/visual/j5_link.DAE" scale="1 1 1" />
            </geometry>
            <material name="">
                <color rgba="0.89804 0.91765 0.92941 1" />
            </material>
        </visual>
        <collision>
            <origin rpy="0 0 0" xyz="0 0 0" />
            <geometry>
                <mesh filename="package://frcobot_description/meshes/fr5v6/collision/j5_link.STL" scale="1 1 1" />
            </geometry>
        </collision>
    </link>
    <joint name="fr5v6_j5" type="revolute">
        <origin rpy="1.5708 0 0" xyz="0 0 0.1021" />
        <parent link="fr5v6_j4_link" />
        <child link="fr5v6_j5_link" />
        <axis xyz="0 0 1" />
        <limit effort="28" lower="-3.0543" upper="3.0543" velocity="3.2" />
        <calibration falling="0" rising="0" />
        <dynamics damping="0" friction="0" />
        <safety_controller k_position="15" k_velocity="10" soft_lower_limit="-3.0543" soft_upper_limit="3.0543" />
    </joint>
    <link name="fr5v6_j6_link">
        <inertial>
            <origin rpy="0 0 0" xyz="7.7496E-05 1.7751E-05 0.076122" />
            <mass value="0.52542" />
            <inertia ixx="0.00027721" ixy="-1.8677e-09" ixz="-1.188e-07" iyy="0.00027839" iyz="2.2607e-07" izz="0.00041605" />
        </inertial>
        <visual>
            <origin rpy="0 0 0" xyz="0 0 0" />
            <geometry>
                <mesh filename="package://frcobot_description/meshes/fr5v6/visual/j6_link.DAE" scale="1 1 1" />
            </geometry>
            <material name="">
                <color rgba="0.89804 0.91765 0.92941 1" />
            </material>
        </visual>
        <collision>
            <origin rpy="0 0 0" xyz="0 0 0" />
            <geometry>
                <mesh filename="package://frcobot_description/meshes/fr5v6/collision/j6_link.STL" scale="1 1 1" />
            </geometry>
        </collision>
    </link>
    <joint name="fr5v6_j6" type="revolute">
        <origin rpy="-1.5708 0 0" xyz="0 0 0.102" />
        <parent link="fr5v6_j5_link" />
        <child link="fr5v6_j6_link" />
        <axis xyz="0 0 1" />
        <limit effort="28" lower="-3.0543" upper="3.0543" velocity="3.2" />
        <calibration falling="0" rising="0" />
        <dynamics damping="0" friction="0" />
        <safety_controller k_position="15" k_velocity="10" soft_lower_limit="-3.0543" soft_upper_limit="3.0543" />
    </joint>
    <!-- Uncomment and modify the following section if you have a tool link -->
    <link name="fr5v6_tool_link">
        <inertial>
            <origin rpy="0 0 0" xyz="0.24412 0.079181 -0.126" />
            <mass value="0" />
            <inertia ixx="0.10666" ixy="-0.046059" ixz="0.046354" iyy="0.87967" iyz="0.0095222" izz="0.85231" />
        </inertial>
        <visual>
            <origin rpy="0 0 0" xyz="0 0 0" />
            <geometry>
                <mesh filename="package://frcobot_description/meshes/fr5v6/visual/toolA-250mm.DAE" scale="0.001 0.001 0.001" />
            </geometry>
            <material name="">
                <color rgba="0.89804 0.91765 0.92941 1" />
            </material>
        </visual>
        <collision>
            <origin rpy="0 0 0" xyz="0 0 0" />
            <geometry>
                <mesh filename="package://frcobot_description/meshes/fr5v6/collision/toolA-250mm.STL" scale="0.001 0.001 0.001" />
            </geometry>
        </collision>
    </link>
    <joint name="fr5v6_tool" type="fixed">
        <origin rpy="0 0 0" xyz="0 0 0.1" />
        <parent link="fr5v6_j6_link" />
        <child link="fr5v6_tool_link" />
        <axis xyz="0 0 1" />
        <limit effort="0" lower="0" upper="0" velocity="0" />
        <calibration falling="0" rising="0" />
        <dynamics damping="0" friction="0" />
        <safety_controller k_position="0" k_velocity="0" soft_lower_limit="0" soft_upper_limit="0" />
    </joint>
    <!-- 添加工具末端TCP坐标系（使用基本几何体） -->
    <link name="fr5v6_tool_tcp_link">
        <inertial>
            <origin rpy="0 0 0" xyz="0 0 0" />
            <mass value="0.001" />
            <inertia ixx="0.0000001" ixy="0" ixz="0" iyy="0.0000001" iyz="0" izz="0.0000001" />
        </inertial>
        <visual>
            <origin rpy="0 0 0" xyz="0 0 0" />
            <geometry>
                <sphere radius="0.005" />
            </geometry>
            <material name="">
                <color rgba="1 0 0 1" />
            </material>
        </visual>
        <!-- 添加碰撞几何体 -->
        <collision>
            <origin rpy="0 0 0" xyz="0 0 0" />
            <geometry>
                <sphere radius="0.005" />
            </geometry>
        </collision>
    </link>
    <joint name="fr5v6_tool_tcp_joint" type="fixed">
        <origin rpy="0 0 0" xyz="0 0 0.25" />
        <parent link="fr5v6_tool_link" />
        <child link="fr5v6_tool_tcp_link" />
    </joint>
    <transmission name="trans_fr5v6_j1">
        <type>transmission_interface/SimpleTransmission</type>
        <joint name="fr5v6_j1">
            <hardwareInterface>hardware_interface/PositionJointInterface</hardwareInterface>
        </joint>
        <actuator name="fr5v6_j1_motor">
            <hardwareInterface>hardware_interface/PositionJointInterface</hardwareInterface>
            <mechanicalReduction>1</mechanicalReduction>
        </actuator>
    </transmission>
    <transmission name="trans_fr5v6_j2">
        <type>transmission_interface/SimpleTransmission</type>
        <joint name="fr5v6_j2">
            <hardwareInterface>hardware_interface/PositionJointInterface</hardwareInterface>
        </joint>
        <actuator name="fr5v6_j2_motor">
            <hardwareInterface>hardware_interface/PositionJointInterface</hardwareInterface>
            <mechanicalReduction>1</mechanicalReduction>
        </actuator>
    </transmission>
    <transmission name="trans_fr5v6_j3">
        <type>transmission_interface/SimpleTransmission</type>
        <joint name="fr5v6_j3">
            <hardwareInterface>hardware_interface/PositionJointInterface</hardwareInterface>
        </joint>
        <actuator name="fr5v6_j3_motor">
            <hardwareInterface>hardware_interface/PositionJointInterface</hardwareInterface>
            <mechanicalReduction>1</mechanicalReduction>
        </actuator>
    </transmission>
    <transmission name="trans_fr5v6_j4">
        <type>transmission_interface/SimpleTransmission</type>
        <joint name="fr5v6_j4">
            <hardwareInterface>hardware_interface/PositionJointInterface</hardwareInterface>
        </joint>
        <actuator name="fr5v6_j4_motor">
            <hardwareInterface>hardware_interface/PositionJointInterface</hardwareInterface>
            <mechanicalReduction>1</mechanicalReduction>
        </actuator>
    </transmission>
    <transmission name="trans_fr5v6_j5">
        <type>transmission_interface/SimpleTransmission</type>
        <joint name="fr5v6_j5">
            <hardwareInterface>hardware_interface/PositionJointInterface</hardwareInterface>
        </joint>
        <actuator name="fr5v6_j5_motor">
            <hardwareInterface>hardware_interface/PositionJointInterface</hardwareInterface>
            <mechanicalReduction>1</mechanicalReduction>
        </actuator>
    </transmission>
    <transmission name="trans_fr5v6_j6">
        <type>transmission_interface/SimpleTransmission</type>
        <joint name="fr5v6_j6">
            <hardwareInterface>hardware_interface/PositionJointInterface</hardwareInterface>
        </joint>
        <actuator name="fr5v6_j6_motor">
            <hardwareInterface>hardware_interface/PositionJointInterface</hardwareInterface>
            <mechanicalReduction>1</mechanicalReduction>
        </actuator>
    </transmission>
    <gazebo>
        <plugin name="gazebo_ros_control" filename="libgazebo_ros_control.so">
            <robotNamespace>/</robotNamespace>
        </plugin>
    </gazebo>
</robot>
