<?xml version="1.0" ?>
<!-- =================================================================================== -->
<!-- |    This document was autogenerated by xacro from /home/lawkaho/workshop/zlab_robots/catkin_ws/src/frcobot_description/urdf/fr5v6_dual_arms.xacro | -->
<!-- |    EDITING THIS FILE BY HAND IS NOT RECOMMENDED                                 | -->
<!-- =================================================================================== -->
<robot name="fr5v6_dual_arms">
    <!-- load arm/hand models and utils (which adds the robot inertia tags to be Gazebo-simulation
    ready) -->
    <!-- <xacro:include filename="$(find franka_description)/robots/common/utils.xacro" /> -->
    <!-- <xacro:include filename="$(find franka_description)/robots/common/franka_arm.xacro" /> -->
    <!-- <xacro:include filename="$(find franka_description)/robots/common/franka_hand.xacro" /> -->
    <link name="world" />
    <!-- box shaped table as base for the 2 Pandas -->
    <!-- <link name="base">
        <visual>
            <origin xyz="0 0 0.5" rpy="0 0 0" />
            <geometry>
                <box size="1 2 1" />
            </geometry>
            <material name="White">
                <color rgba="1.0 1.0 1.0 1.0" />
            </material>
        </visual>
        <collision>
            <origin xyz="0 0 0.5" rpy="0 0 0" />
            <geometry>
                <box size="1 2 1" />
            </geometry>
        </collision>
        <inertial>
            <origin xyz="0.0 0.0 0.0" rpy="0.0 0.0 0.0" />
            <mass value="10.0" />
            <inertia ixx="0.001" ixy="0.0" ixz="0.001" iyy="0.0" iyz="0.0" izz="0.001" />
        </inertial>

    </link> -->
    <!-- <joint name="base_to_world" type="fixed">
        <parent link="world" />
        <child link="base" />
        <origin xyz="0.0 0.0 0.0" rpy="0.0 0.0 0.0" />
    </joint> -->
    <!-- right arm with gripper -->
    <!-- <xacro:fr5v6_arm arm_id="$(arg arm_id_1)" connected_to="base" xyz="0 -0.5 1" 
        gazebo="true"
        safety_distance="0.03"
        joint_limits="${xacro.load_yaml('$(find fr5v6_moveit_config)/config/joint_limits.yaml')}" 
        /> -->
    <!-- <xacro:franka_hand arm_id="$(arg arm_id_1)" rpy="0 0 ${-pi/4}"
        connected_to="$(arg arm_id_1)_link8" gazebo="true" safety_distance="0.03" /> -->
    <!-- left arm with gripper -->
    <!-- <xacro:fr5v6_arm arm_id="$(arg arm_id_2)" connected_to="base" xyz="0 0.5 1" gazebo="true"
        safety_distance="0.03"
        joint_limits="${xacro.load_yaml('$(find fr5v6_moveit_config)/config/joint_limits.yaml')}" /> -->
    <!-- <xacro:franka_hand arm_id="$(arg arm_id_2)" rpy="0 0 ${-pi/4}"
        connected_to="$(arg arm_id_2)_link8" gazebo="true" safety_distance="0.03" /> -->
    <joint name="robot1_joint_base" type="fixed">
        <parent link="world" />
        <child link="robot1_extra_base_link" />
        <origin rpy="0 0 0" xyz="0 -0.5 0" />
    </joint>
    <link name="robot1_extra_base_link">
        <inertial>
            <origin rpy="0 0 0" xyz="-0.00035477 0.0011738 0.038422" />
            <mass value="6.8715" />
            <inertia ixx="0.11261" ixy="-2.8693e-05" ixz="-0.0017586" iyy="0.11265" iyz="0.002588" izz="0.19704" />
        </inertial>
        <visual>
            <origin rpy="0 0 0" xyz="0 0 0" />
            <geometry>
                <mesh filename="package://frcobot_description/meshes/fr5v6/visual/extra_base_link.DAE" />
            </geometry>
            <material name="">
                <color rgba="0.89804 0.91765 0.92941 1" />
            </material>
        </visual>
        <collision>
            <origin rpy="0 0 0" xyz="0 0 0" />
            <geometry>
                <mesh filename="package://frcobot_description/meshes/fr5v6/collision/extra_base_link.STL" />
            </geometry>
        </collision>
    </link>
    <joint name="robot1_extra_base_to_plant" type="fixed">
        <parent link="robot1_extra_base_link" />
        <child link="robot1_plant_link" />
        <origin rpy="0 0 0" xyz="-0.00031408 0.00046097 0.41799" />
    </joint>
    <link name="robot1_plant_link">
        <inertial>
            <origin rpy="0 0 0" xyz="2.7756E-16 0 -0.008" />
            <mass value="0.40503" />
            <inertia ixx="0.0008273" ixy="-2.5374e-19" ixz="1.6905e-22" iyy="0.0008273" iyz="-2.1817e-22" izz="0.0016373" />
        </inertial>
        <visual>
            <origin rpy="0 0 0" xyz="0 0 0" />
            <geometry>
                <mesh filename="package://frcobot_description/meshes/fr5v6/visual/plant_link.DAE" />
            </geometry>
            <material name="">
                <color rgba="0.89804 0.91765 0.92941 1" />
            </material>
        </visual>
        <collision>
            <origin rpy="0 0 0" xyz="0 0 0" />
            <geometry>
                <mesh filename="package://frcobot_description/meshes/fr5v6/collision/plant_link.STL" />
            </geometry>
        </collision>
    </link>
    <joint name="robot1_extra_plant_to_base" type="fixed">
        <parent link="robot1_plant_link" />
        <child link="robot1_base_link" />
        <origin rpy="0 0 0" xyz="0 0 0.0001" />
    </joint>
    <link name="robot1_base_link">
        <inertial>
            <origin rpy="0 0 0" xyz="-0.00031896 -0.00029673 0.042463" />
            <mass value="1.6185" />
            <inertia ixx="0.0030836" ixy="1.5354e-05" ixz="-1.9315e-05" iyy="0.0030825" iyz="-1.7918e-05" izz="0.0045209" />
        </inertial>
        <visual>
            <origin rpy="0 0 0" xyz="0 0 0" />
            <geometry>
                <mesh filename="package://frcobot_description/meshes/fr5v6/visual/base_link.DAE" />
            </geometry>
            <material name="">
                <color rgba="0.89804 0.91765 0.92941 1" />
            </material>
        </visual>
        <collision>
            <origin rpy="0 0 0" xyz="0 0 0" />
            <geometry>
                <mesh filename="package://frcobot_description/meshes/fr5v6/collision/base_link.STL" />
            </geometry>
        </collision>
    </link>
    <link name="robot1_j1_Link">
        <inertial>
            <origin rpy="0 0 0" xyz="5.0029E-07 -0.0040922 0.14629" />
            <mass value="4.3771" />
            <inertia ixx="0.010731" ixy="-8.0587e-09" ixz="-3.6773e-08" iyy="0.010408" iyz="0.00012853" izz="0.0081793" />
        </inertial>
        <visual>
            <origin rpy="0 0 0" xyz="0 0 0" />
            <geometry>
                <mesh filename="package://frcobot_description/meshes/fr5v6/visual/j1_Link.DAE" />
            </geometry>
            <material name="">
                <color rgba="0.89804 0.91765 0.92941 1" />
            </material>
        </visual>
        <collision>
            <origin rpy="0 0 0" xyz="0 0 0" />
            <geometry>
                <mesh filename="package://frcobot_description/meshes/fr5v6/collision/j1_Link.STL" />
            </geometry>
        </collision>
    </link>
    <joint name="robot1_j1" type="revolute">
        <origin rpy="0 0 0" xyz="0 0 0" />
        <parent link="robot1_base_link" />
        <child link="robot1_j1_Link" />
        <axis xyz="0 0 1" />
        <limit effort="150" lower="-3.0543" upper="3.0543" velocity="3.15" />
        <calibration falling="0" rising="0" />
        <dynamics damping="0" friction="0" />
        <safety_controller k_position="15" k_velocity="10" soft_lower_limit="-3.0543" soft_upper_limit="3.0543" />
    </joint>
    <link name="robot1_j2_Link">
        <inertial>
            <origin rpy="0 0 0" xyz="-0.2125 -5.7643E-09 0.1346" />
            <mass value="14.458" />
            <inertia ixx="0.028392" ixy="-1.337e-07" ixz="-3.9895e-09" iyy="0.4559" iyz="4.214e-08" izz="0.44974" />
        </inertial>
        <visual>
            <origin rpy="0 0 0" xyz="0 0 0" />
            <geometry>
                <mesh filename="package://frcobot_description/meshes/fr5v6/visual/j2_Link.DAE" />
            </geometry>
            <material name="">
                <color rgba="0.89804 0.91765 0.92941 1" />
            </material>
        </visual>
        <collision>
            <origin rpy="0 0 0" xyz="0 0 0" />
            <geometry>
                <mesh filename="package://frcobot_description/meshes/fr5v6/collision/j2_Link.STL" />
            </geometry>
        </collision>
    </link>
    <joint name="robot1_j2" type="revolute">
        <origin rpy="1.5708 0 0" xyz="0 0 0.152" />
        <parent link="robot1_j1_Link" />
        <child link="robot1_j2_Link" />
        <axis xyz="0 0 1" />
        <limit effort="150" lower="-4.6251" upper="1.4835" velocity="3.15" />
        <calibration falling="0" rising="0" />
        <dynamics damping="0" friction="0" />
        <safety_controller k_position="15" k_velocity="10" soft_lower_limit="-4.6251" soft_upper_limit="1.4835" />
    </joint>
    <link name="robot1_j3_Link">
        <inertial>
            <origin rpy="0 0 0" xyz="-0.18793 -8.4503E-07 0.0066357" />
            <mass value="7.6737" />
            <inertia ixx="0.0085096" ixy="2.1613e-06" ixz="-0.0068678" iyy="0.16971" iyz="3.7086e-08" izz="0.16854" />
        </inertial>
        <visual>
            <origin rpy="0 0 0" xyz="0 0 0" />
            <geometry>
                <mesh filename="package://frcobot_description/meshes/fr5v6/visual/j3_Link.DAE" />
            </geometry>
            <material name="">
                <color rgba="0.89804 0.91765 0.92941 1" />
            </material>
        </visual>
        <collision>
            <origin rpy="0 0 0" xyz="0 0 0" />
            <geometry>
                <mesh filename="package://frcobot_description/meshes/fr5v6/collision/j3_Link.STL" />
            </geometry>
        </collision>
    </link>
    <joint name="robot1_j3" type="revolute">
        <origin rpy="0 0 0" xyz="-0.425 0 0" />
        <parent link="robot1_j2_Link" />
        <child link="robot1_j3_Link" />
        <axis xyz="0 0 1" />
        <limit effort="150" lower="-2.8274" upper="2.8274" velocity="3.15" />
        <calibration falling="0" rising="0" />
        <dynamics damping="0" friction="0" />
        <safety_controller k_position="15" k_velocity="10" soft_lower_limit="-2.8274" soft_upper_limit="2.8274" />
    </joint>
    <link name="robot1_j4_Link">
        <inertial>
            <origin rpy="0 0 0" xyz="4.98E-07 -0.003754 0.097155" />
            <mass value="1.6266" />
            <inertia ixx="0.00216" ixy="4.888e-09" ixz="3.1528e-08" iyy="0.0015455" iyz="3.7678e-05" izz="0.0019902" />
        </inertial>
        <visual>
            <origin rpy="0 0 0" xyz="0 0 0" />
            <geometry>
                <mesh filename="package://frcobot_description/meshes/fr5v6/visual/j4_Link.DAE" />
            </geometry>
            <material name="">
                <color rgba="0.89804 0.91765 0.92941 1" />
            </material>
        </visual>
        <collision>
            <origin rpy="0 0 0" xyz="0 0 0" />
            <geometry>
                <mesh filename="package://frcobot_description/meshes/fr5v6/collision/j4_Link.STL" />
            </geometry>
        </collision>
    </link>
    <joint name="robot1_j4" type="revolute">
        <origin rpy="0 0 0" xyz="-0.39501 0 0" />
        <parent link="robot1_j3_Link" />
        <child link="robot1_j4_Link" />
        <axis xyz="0 0 1" />
        <limit effort="28" lower="-4.6251" upper="1.4835" velocity="3.2" />
        <calibration falling="0" rising="0" />
        <dynamics damping="0" friction="0" />
        <safety_controller k_position="15" k_velocity="10" soft_lower_limit="-4.6251" soft_upper_limit="1.4835" />
    </joint>
    <link name="robot1_j5_Link">
        <inertial>
            <origin rpy="0 0 0" xyz="-4.5588E-07 0.0038617 0.098257" />
            <mass value="1.5812" />
            <inertia ixx="0.0020612" ixy="8.7064e-09" ixz="-3.4742e-08" iyy="0.0014477" iyz="-2.8534e-05" izz="0.0019573" />
        </inertial>
        <visual>
            <origin rpy="0 0 0" xyz="0 0 0" />
            <geometry>
                <mesh filename="package://frcobot_description/meshes/fr5v6/visual/j5_Link.DAE" />
            </geometry>
            <material name="">
                <color rgba="0.89804 0.91765 0.92941 1" />
            </material>
        </visual>
        <collision>
            <origin rpy="0 0 0" xyz="0 0 0" />
            <geometry>
                <mesh filename="package://frcobot_description/meshes/fr5v6/collision/j5_Link.STL" />
            </geometry>
        </collision>
    </link>
    <joint name="robot1_j5" type="revolute">
        <origin rpy="1.5708 0 0" xyz="0 0 0.1021" />
        <parent link="robot1_j4_Link" />
        <child link="robot1_j5_Link" />
        <axis xyz="0 0 1" />
        <limit effort="28" lower="-3.0543" upper="3.0543" velocity="3.2" />
        <calibration falling="0" rising="0" />
        <dynamics damping="0" friction="0" />
        <safety_controller k_position="15" k_velocity="10" soft_lower_limit="-3.0543" soft_upper_limit="3.0543" />
    </joint>
    <link name="robot1_j6_Link">
        <inertial>
            <origin rpy="0 0 0" xyz="7.7496E-05 1.7751E-05 0.076122" />
            <mass value="0.52542" />
            <inertia ixx="0.00027721" ixy="-1.8677e-09" ixz="-1.188e-07" iyy="0.00027839" iyz="2.2607e-07" izz="0.00041605" />
        </inertial>
        <visual>
            <origin rpy="0 0 0" xyz="0 0 0" />
            <geometry>
                <mesh filename="package://frcobot_description/meshes/fr5v6/visual/j6_Link.DAE" />
            </geometry>
            <material name="">
                <color rgba="0.89804 0.91765 0.92941 1" />
            </material>
        </visual>
        <collision>
            <origin rpy="0 0 0" xyz="0 0 0" />
            <geometry>
                <mesh filename="package://frcobot_description/meshes/fr5v6/collision/j6_Link.STL" />
            </geometry>
        </collision>
    </link>
    <joint name="robot1_j6" type="revolute">
        <origin rpy="-1.5708 0 0" xyz="0 0 0.102" />
        <parent link="robot1_j5_Link" />
        <child link="robot1_j6_Link" />
        <axis xyz="0 0 1" />
        <limit effort="28" lower="-3.0543" upper="3.0543" velocity="3.2" />
        <calibration falling="0" rising="0" />
        <dynamics damping="0" friction="0" />
        <safety_controller k_position="15" k_velocity="10" soft_lower_limit="-3.0543" soft_upper_limit="3.0543" />
    </joint>
    <joint name="robot2_joint_base" type="fixed">
        <parent link="world" />
        <child link="robot2_extra_base_link" />
        <origin rpy="0 0 0" xyz="0 0.5 0" />
    </joint>
    <link name="robot2_extra_base_link">
        <inertial>
            <origin rpy="0 0 0" xyz="-0.00035477 0.0011738 0.038422" />
            <mass value="6.8715" />
            <inertia ixx="0.11261" ixy="-2.8693e-05" ixz="-0.0017586" iyy="0.11265" iyz="0.002588" izz="0.19704" />
        </inertial>
        <visual>
            <origin rpy="0 0 0" xyz="0 0 0" />
            <geometry>
                <mesh filename="package://frcobot_description/meshes/fr5v6/visual/extra_base_link.DAE" />
            </geometry>
            <material name="">
                <color rgba="0.89804 0.91765 0.92941 1" />
            </material>
        </visual>
        <collision>
            <origin rpy="0 0 0" xyz="0 0 0" />
            <geometry>
                <mesh filename="package://frcobot_description/meshes/fr5v6/collision/extra_base_link.STL" />
            </geometry>
        </collision>
    </link>
    <joint name="robot2_extra_base_to_plant" type="fixed">
        <parent link="robot2_extra_base_link" />
        <child link="robot2_plant_link" />
        <origin rpy="0 0 0" xyz="-0.00031408 0.00046097 0.41799" />
    </joint>
    <link name="robot2_plant_link">
        <inertial>
            <origin rpy="0 0 0" xyz="2.7756E-16 0 -0.008" />
            <mass value="0.40503" />
            <inertia ixx="0.0008273" ixy="-2.5374e-19" ixz="1.6905e-22" iyy="0.0008273" iyz="-2.1817e-22" izz="0.0016373" />
        </inertial>
        <visual>
            <origin rpy="0 0 0" xyz="0 0 0" />
            <geometry>
                <mesh filename="package://frcobot_description/meshes/fr5v6/visual/plant_link.DAE" />
            </geometry>
            <material name="">
                <color rgba="0.89804 0.91765 0.92941 1" />
            </material>
        </visual>
        <collision>
            <origin rpy="0 0 0" xyz="0 0 0" />
            <geometry>
                <mesh filename="package://frcobot_description/meshes/fr5v6/collision/plant_link.STL" />
            </geometry>
        </collision>
    </link>
    <joint name="robot2_extra_plant_to_base" type="fixed">
        <parent link="robot2_plant_link" />
        <child link="robot2_base_link" />
        <origin rpy="0 0 0" xyz="0 0 0.0001" />
    </joint>
    <link name="robot2_base_link">
        <inertial>
            <origin rpy="0 0 0" xyz="-0.00031896 -0.00029673 0.042463" />
            <mass value="1.6185" />
            <inertia ixx="0.0030836" ixy="1.5354e-05" ixz="-1.9315e-05" iyy="0.0030825" iyz="-1.7918e-05" izz="0.0045209" />
        </inertial>
        <visual>
            <origin rpy="0 0 0" xyz="0 0 0" />
            <geometry>
                <mesh filename="package://frcobot_description/meshes/fr5v6/visual/base_link.DAE" />
            </geometry>
            <material name="">
                <color rgba="0.89804 0.91765 0.92941 1" />
            </material>
        </visual>
        <collision>
            <origin rpy="0 0 0" xyz="0 0 0" />
            <geometry>
                <mesh filename="package://frcobot_description/meshes/fr5v6/collision/base_link.STL" />
            </geometry>
        </collision>
    </link>
    <link name="robot2_j1_Link">
        <inertial>
            <origin rpy="0 0 0" xyz="5.0029E-07 -0.0040922 0.14629" />
            <mass value="4.3771" />
            <inertia ixx="0.010731" ixy="-8.0587e-09" ixz="-3.6773e-08" iyy="0.010408" iyz="0.00012853" izz="0.0081793" />
        </inertial>
        <visual>
            <origin rpy="0 0 0" xyz="0 0 0" />
            <geometry>
                <mesh filename="package://frcobot_description/meshes/fr5v6/visual/j1_Link.DAE" />
            </geometry>
            <material name="">
                <color rgba="0.89804 0.91765 0.92941 1" />
            </material>
        </visual>
        <collision>
            <origin rpy="0 0 0" xyz="0 0 0" />
            <geometry>
                <mesh filename="package://frcobot_description/meshes/fr5v6/collision/j1_Link.STL" />
            </geometry>
        </collision>
    </link>
    <joint name="robot2_j1" type="revolute">
        <origin rpy="0 0 0" xyz="0 0 0" />
        <parent link="robot2_base_link" />
        <child link="robot2_j1_Link" />
        <axis xyz="0 0 1" />
        <limit effort="150" lower="-3.0543" upper="3.0543" velocity="3.15" />
        <calibration falling="0" rising="0" />
        <dynamics damping="0" friction="0" />
        <safety_controller k_position="15" k_velocity="10" soft_lower_limit="-3.0543" soft_upper_limit="3.0543" />
    </joint>
    <link name="robot2_j2_Link">
        <inertial>
            <origin rpy="0 0 0" xyz="-0.2125 -5.7643E-09 0.1346" />
            <mass value="14.458" />
            <inertia ixx="0.028392" ixy="-1.337e-07" ixz="-3.9895e-09" iyy="0.4559" iyz="4.214e-08" izz="0.44974" />
        </inertial>
        <visual>
            <origin rpy="0 0 0" xyz="0 0 0" />
            <geometry>
                <mesh filename="package://frcobot_description/meshes/fr5v6/visual/j2_Link.DAE" />
            </geometry>
            <material name="">
                <color rgba="0.89804 0.91765 0.92941 1" />
            </material>
        </visual>
        <collision>
            <origin rpy="0 0 0" xyz="0 0 0" />
            <geometry>
                <mesh filename="package://frcobot_description/meshes/fr5v6/collision/j2_Link.STL" />
            </geometry>
        </collision>
    </link>
    <joint name="robot2_j2" type="revolute">
        <origin rpy="1.5708 0 0" xyz="0 0 0.152" />
        <parent link="robot2_j1_Link" />
        <child link="robot2_j2_Link" />
        <axis xyz="0 0 1" />
        <limit effort="150" lower="-4.6251" upper="1.4835" velocity="3.15" />
        <calibration falling="0" rising="0" />
        <dynamics damping="0" friction="0" />
        <safety_controller k_position="15" k_velocity="10" soft_lower_limit="-4.6251" soft_upper_limit="1.4835" />
    </joint>
    <link name="robot2_j3_Link">
        <inertial>
            <origin rpy="0 0 0" xyz="-0.18793 -8.4503E-07 0.0066357" />
            <mass value="7.6737" />
            <inertia ixx="0.0085096" ixy="2.1613e-06" ixz="-0.0068678" iyy="0.16971" iyz="3.7086e-08" izz="0.16854" />
        </inertial>
        <visual>
            <origin rpy="0 0 0" xyz="0 0 0" />
            <geometry>
                <mesh filename="package://frcobot_description/meshes/fr5v6/visual/j3_Link.DAE" />
            </geometry>
            <material name="">
                <color rgba="0.89804 0.91765 0.92941 1" />
            </material>
        </visual>
        <collision>
            <origin rpy="0 0 0" xyz="0 0 0" />
            <geometry>
                <mesh filename="package://frcobot_description/meshes/fr5v6/collision/j3_Link.STL" />
            </geometry>
        </collision>
    </link>
    <joint name="robot2_j3" type="revolute">
        <origin rpy="0 0 0" xyz="-0.425 0 0" />
        <parent link="robot2_j2_Link" />
        <child link="robot2_j3_Link" />
        <axis xyz="0 0 1" />
        <limit effort="150" lower="-2.8274" upper="2.8274" velocity="3.15" />
        <calibration falling="0" rising="0" />
        <dynamics damping="0" friction="0" />
        <safety_controller k_position="15" k_velocity="10" soft_lower_limit="-2.8274" soft_upper_limit="2.8274" />
    </joint>
    <link name="robot2_j4_Link">
        <inertial>
            <origin rpy="0 0 0" xyz="4.98E-07 -0.003754 0.097155" />
            <mass value="1.6266" />
            <inertia ixx="0.00216" ixy="4.888e-09" ixz="3.1528e-08" iyy="0.0015455" iyz="3.7678e-05" izz="0.0019902" />
        </inertial>
        <visual>
            <origin rpy="0 0 0" xyz="0 0 0" />
            <geometry>
                <mesh filename="package://frcobot_description/meshes/fr5v6/visual/j4_Link.DAE" />
            </geometry>
            <material name="">
                <color rgba="0.89804 0.91765 0.92941 1" />
            </material>
        </visual>
        <collision>
            <origin rpy="0 0 0" xyz="0 0 0" />
            <geometry>
                <mesh filename="package://frcobot_description/meshes/fr5v6/collision/j4_Link.STL" />
            </geometry>
        </collision>
    </link>
    <joint name="robot2_j4" type="revolute">
        <origin rpy="0 0 0" xyz="-0.39501 0 0" />
        <parent link="robot2_j3_Link" />
        <child link="robot2_j4_Link" />
        <axis xyz="0 0 1" />
        <limit effort="28" lower="-4.6251" upper="1.4835" velocity="3.2" />
        <calibration falling="0" rising="0" />
        <dynamics damping="0" friction="0" />
        <safety_controller k_position="15" k_velocity="10" soft_lower_limit="-4.6251" soft_upper_limit="1.4835" />
    </joint>
    <link name="robot2_j5_Link">
        <inertial>
            <origin rpy="0 0 0" xyz="-4.5588E-07 0.0038617 0.098257" />
            <mass value="1.5812" />
            <inertia ixx="0.0020612" ixy="8.7064e-09" ixz="-3.4742e-08" iyy="0.0014477" iyz="-2.8534e-05" izz="0.0019573" />
        </inertial>
        <visual>
            <origin rpy="0 0 0" xyz="0 0 0" />
            <geometry>
                <mesh filename="package://frcobot_description/meshes/fr5v6/visual/j5_Link.DAE" />
            </geometry>
            <material name="">
                <color rgba="0.89804 0.91765 0.92941 1" />
            </material>
        </visual>
        <collision>
            <origin rpy="0 0 0" xyz="0 0 0" />
            <geometry>
                <mesh filename="package://frcobot_description/meshes/fr5v6/collision/j5_Link.STL" />
            </geometry>
        </collision>
    </link>
    <joint name="robot2_j5" type="revolute">
        <origin rpy="1.5708 0 0" xyz="0 0 0.1021" />
        <parent link="robot2_j4_Link" />
        <child link="robot2_j5_Link" />
        <axis xyz="0 0 1" />
        <limit effort="28" lower="-3.0543" upper="3.0543" velocity="3.2" />
        <calibration falling="0" rising="0" />
        <dynamics damping="0" friction="0" />
        <safety_controller k_position="15" k_velocity="10" soft_lower_limit="-3.0543" soft_upper_limit="3.0543" />
    </joint>
    <link name="robot2_j6_Link">
        <inertial>
            <origin rpy="0 0 0" xyz="7.7496E-05 1.7751E-05 0.076122" />
            <mass value="0.52542" />
            <inertia ixx="0.00027721" ixy="-1.8677e-09" ixz="-1.188e-07" iyy="0.00027839" iyz="2.2607e-07" izz="0.00041605" />
        </inertial>
        <visual>
            <origin rpy="0 0 0" xyz="0 0 0" />
            <geometry>
                <mesh filename="package://frcobot_description/meshes/fr5v6/visual/j6_Link.DAE" />
            </geometry>
            <material name="">
                <color rgba="0.89804 0.91765 0.92941 1" />
            </material>
        </visual>
        <collision>
            <origin rpy="0 0 0" xyz="0 0 0" />
            <geometry>
                <mesh filename="package://frcobot_description/meshes/fr5v6/collision/j6_Link.STL" />
            </geometry>
        </collision>
    </link>
    <joint name="robot2_j6" type="revolute">
        <origin rpy="-1.5708 0 0" xyz="0 0 0.102" />
        <parent link="robot2_j5_Link" />
        <child link="robot2_j6_Link" />
        <axis xyz="0 0 1" />
        <limit effort="28" lower="-3.0543" upper="3.0543" velocity="3.2" />
        <calibration falling="0" rising="0" />
        <dynamics damping="0" friction="0" />
        <safety_controller k_position="15" k_velocity="10" soft_lower_limit="-3.0543" soft_upper_limit="3.0543" />
    </joint>
    <transmission name="trans_robot1_j1">
        <type>transmission_interface/SimpleTransmission</type>
        <joint name="robot1_j1">
            <hardwareInterface>hardware_interface/PositionJointInterface</hardwareInterface>
        </joint>
        <actuator name="robot1_j1_motor">
            <hardwareInterface>hardware_interface/PositionJointInterface</hardwareInterface>
            <mechanicalReduction>1</mechanicalReduction>
        </actuator>
    </transmission>
    <transmission name="trans_robot1_j2">
        <type>transmission_interface/SimpleTransmission</type>
        <joint name="robot1_j2">
            <hardwareInterface>hardware_interface/PositionJointInterface</hardwareInterface>
        </joint>
        <actuator name="robot1_j2_motor">
            <hardwareInterface>hardware_interface/PositionJointInterface</hardwareInterface>
            <mechanicalReduction>1</mechanicalReduction>
        </actuator>
    </transmission>
    <transmission name="trans_robot1_j3">
        <type>transmission_interface/SimpleTransmission</type>
        <joint name="robot1_j3">
            <hardwareInterface>hardware_interface/PositionJointInterface</hardwareInterface>
        </joint>
        <actuator name="robot1_j3_motor">
            <hardwareInterface>hardware_interface/PositionJointInterface</hardwareInterface>
            <mechanicalReduction>1</mechanicalReduction>
        </actuator>
    </transmission>
    <transmission name="trans_robot1_j4">
        <type>transmission_interface/SimpleTransmission</type>
        <joint name="robot1_j4">
            <hardwareInterface>hardware_interface/PositionJointInterface</hardwareInterface>
        </joint>
        <actuator name="robot1_j4_motor">
            <hardwareInterface>hardware_interface/PositionJointInterface</hardwareInterface>
            <mechanicalReduction>1</mechanicalReduction>
        </actuator>
    </transmission>
    <transmission name="trans_robot1_j5">
        <type>transmission_interface/SimpleTransmission</type>
        <joint name="robot1_j5">
            <hardwareInterface>hardware_interface/PositionJointInterface</hardwareInterface>
        </joint>
        <actuator name="robot1_j5_motor">
            <hardwareInterface>hardware_interface/PositionJointInterface</hardwareInterface>
            <mechanicalReduction>1</mechanicalReduction>
        </actuator>
    </transmission>
    <transmission name="trans_robot1_j6">
        <type>transmission_interface/SimpleTransmission</type>
        <joint name="robot1_j6">
            <hardwareInterface>hardware_interface/PositionJointInterface</hardwareInterface>
        </joint>
        <actuator name="robot1_j6_motor">
            <hardwareInterface>hardware_interface/PositionJointInterface</hardwareInterface>
            <mechanicalReduction>1</mechanicalReduction>
        </actuator>
    </transmission>
    <!-- <xacro:gazebo-joint joint="$(arg arm_id_1)_joint7"
        transmission="hardware_interface/PositionJointInterface" /> -->
    <transmission name="trans_robot2_j1">
        <type>transmission_interface/SimpleTransmission</type>
        <joint name="robot2_j1">
            <hardwareInterface>hardware_interface/PositionJointInterface</hardwareInterface>
        </joint>
        <actuator name="robot2_j1_motor">
            <hardwareInterface>hardware_interface/PositionJointInterface</hardwareInterface>
            <mechanicalReduction>1</mechanicalReduction>
        </actuator>
    </transmission>
    <transmission name="trans_robot2_j2">
        <type>transmission_interface/SimpleTransmission</type>
        <joint name="robot2_j2">
            <hardwareInterface>hardware_interface/PositionJointInterface</hardwareInterface>
        </joint>
        <actuator name="robot2_j2_motor">
            <hardwareInterface>hardware_interface/PositionJointInterface</hardwareInterface>
            <mechanicalReduction>1</mechanicalReduction>
        </actuator>
    </transmission>
    <transmission name="trans_robot2_j3">
        <type>transmission_interface/SimpleTransmission</type>
        <joint name="robot2_j3">
            <hardwareInterface>hardware_interface/PositionJointInterface</hardwareInterface>
        </joint>
        <actuator name="robot2_j3_motor">
            <hardwareInterface>hardware_interface/PositionJointInterface</hardwareInterface>
            <mechanicalReduction>1</mechanicalReduction>
        </actuator>
    </transmission>
    <transmission name="trans_robot2_j4">
        <type>transmission_interface/SimpleTransmission</type>
        <joint name="robot2_j4">
            <hardwareInterface>hardware_interface/PositionJointInterface</hardwareInterface>
        </joint>
        <actuator name="robot2_j4_motor">
            <hardwareInterface>hardware_interface/PositionJointInterface</hardwareInterface>
            <mechanicalReduction>1</mechanicalReduction>
        </actuator>
    </transmission>
    <transmission name="trans_robot2_j5">
        <type>transmission_interface/SimpleTransmission</type>
        <joint name="robot2_j5">
            <hardwareInterface>hardware_interface/PositionJointInterface</hardwareInterface>
        </joint>
        <actuator name="robot2_j5_motor">
            <hardwareInterface>hardware_interface/PositionJointInterface</hardwareInterface>
            <mechanicalReduction>1</mechanicalReduction>
        </actuator>
    </transmission>
    <transmission name="trans_robot2_j6">
        <type>transmission_interface/SimpleTransmission</type>
        <joint name="robot2_j6">
            <hardwareInterface>hardware_interface/PositionJointInterface</hardwareInterface>
        </joint>
        <actuator name="robot2_j6_motor">
            <hardwareInterface>hardware_interface/PositionJointInterface</hardwareInterface>
            <mechanicalReduction>1</mechanicalReduction>
        </actuator>
    </transmission>
    <!-- <xacro:gazebo-joint joint="$(arg arm_id_2)_joint7"
        transmission="hardware_interface/PositionJointInterface" /> -->
    <!-- right hand joints control interface -->
    <!-- <xacro:gazebo-joint joint="$(arg arm_id_1)_finger_joint1"
        transmission="hardware_interface/EffortJointInterface" />
    <xacro:gazebo-joint joint="$(arg arm_id_1)_finger_joint2"
        transmission="hardware_interface/EffortJointInterface" /> -->
    <!-- left hand joints control interface -->
    <!-- <xacro:gazebo-joint joint="$(arg arm_id_2)_finger_joint1"
        transmission="hardware_interface/EffortJointInterface" />
    <xacro:gazebo-joint joint="$(arg arm_id_2)_finger_joint2"
        transmission="hardware_interface/EffortJointInterface" /> -->
    <!-- load ros_control plugin -->
    <gazebo>
        <plugin filename="libgazebo_ros_control.so" name="gazebo_ros_control">
            <robotNamespace>/</robotNamespace>
        </plugin>
    </gazebo>
</robot>

