<?xml version="1.0" encoding="utf-8"?>
<robot name="fr5v6" xmlns:xacro="http://www.ros.org/wiki/xacro">
    <xacro:macro name="fr5v6_arm"
        params="arm_id:='fr5v6' connected_to:='' xyz:='0 0 0' rpy:='0 0 0'">
        <xacro:unless value="${not connected_to}">
            <joint name="${arm_id}_joint_base" type="fixed">
                <parent link="${connected_to}" />
                <child link="${arm_id}_extra_base_link" />
                <origin rpy="${rpy}" xyz="${xyz}" />
            </joint>
        </xacro:unless>

        <!-- 定义一些常用的属性 -->
        <xacro:property name="color" value="0.89804 0.91765 0.92941 1" />
        <xacro:property name="material_name" value="" />

        <xacro:macro name="link_with_inertial"
            params="name xyz rpy mass ixx ixy ixz iyy iyz izz visual_mesh collision_mesh scale:='1 1 1'">
            <link name="${name}">
                <inertial>
                    <origin xyz="${xyz}" rpy="${rpy}" />
                    <mass value="${mass}" />
                    <inertia ixx="${ixx}" ixy="${ixy}" ixz="${ixz}" iyy="${iyy}" iyz="${iyz}"
                        izz="${izz}" />
                </inertial>
                <visual>
                    <origin xyz="0 0 0" rpy="0 0 0" />
                    <geometry>
                        <mesh filename="${visual_mesh}" scale="${scale}"/>
                    </geometry>
                    <material name="${material_name}">
                        <color rgba="${color}" />
                    </material>
                </visual>
                <collision>
                    <origin xyz="0 0 0" rpy="0 0 0" />
                    <geometry>
                        <mesh filename="${collision_mesh}" scale="${scale}"/>
                    </geometry>
                </collision>
            </link>
        </xacro:macro>


        <xacro:link_with_inertial name="${arm_id}_extra_base_link"
            xyz="-0.00035477 0.0011738 0.038422"
            rpy="0 0 0"
            mass="6.8715"
            ixx="0.11261"
            ixy="-2.8693E-05"
            ixz="-0.0017586"
            iyy="0.11265"
            iyz="0.002588"
            izz="0.19704"
            visual_mesh="package://frcobot_description/meshes/fr5v6/visual/extra_base_link.DAE"
            collision_mesh="package://frcobot_description/meshes/fr5v6/collision/extra_base_link.STL" />

        <joint name="${arm_id}_extra_base_to_plant" type="fixed">
            <parent link="${arm_id}_extra_base_link" />
            <child link="${arm_id}_plant_link" />
            <origin xyz="-0.00031408 0.00046097 0.41799" rpy="0 0 0" />
        </joint>

        <xacro:link_with_inertial name="${arm_id}_plant_link" xyz="2.7756E-16 0 -0.008"
            rpy="0 0 0"
            mass="0.40503"
            ixx="0.0008273"
            ixy="-2.5374E-19"
            ixz="1.6905E-22"
            iyy="0.0008273"
            iyz="-2.1817E-22"
            izz="0.0016373"
            visual_mesh="package://frcobot_description/meshes/fr5v6/visual/plant_link.DAE"
            collision_mesh="package://frcobot_description/meshes/fr5v6/collision/plant_link.STL" />

        <joint name="${arm_id}_extra_plant_to_base" type="fixed">
            <parent link="${arm_id}_plant_link" />
            <child link="${arm_id}_base_link" />
            <origin xyz="0 0 0.0001" rpy="0 0 0" />
        </joint>

        <xacro:link_with_inertial name="${arm_id}_base_link" xyz="-0.00031896 -0.00029673 0.042463"
            rpy="0 0 0"
            mass="1.6185"
            ixx="0.0030836" ixy="1.5354E-05" ixz="-1.9315E-05" iyy="0.0030825" iyz="-1.7918E-05"
            izz="0.0045209"
            visual_mesh="package://frcobot_description/meshes/fr5v6/visual/base_link.DAE"
            collision_mesh="package://frcobot_description/meshes/fr5v6/collision/base_link.STL" />

        <xacro:link_with_inertial name="${arm_id}_j1_link" xyz="5.0029E-07 -0.0040922 0.14629"
            rpy="0 0 0"
            mass="4.3771"
            ixx="0.010731" ixy="-8.0587E-09" ixz="-3.6773E-08" iyy="0.010408" iyz="0.00012853"
            izz="0.0081793"
            visual_mesh="package://frcobot_description/meshes/fr5v6/visual/j1_link.DAE"
            collision_mesh="package://frcobot_description/meshes/fr5v6/collision/j1_link.STL" />

        <joint name="${arm_id}_j1" type="revolute">
            <origin xyz="0 0 0" rpy="0 0 0" />
            <parent link="${arm_id}_base_link" />
            <child link="${arm_id}_j1_link" />
            <axis xyz="0 0 1" />
            <limit lower="-3.0543" upper="3.0543" effort="150" velocity="3.15" />
            <calibration rising="0" falling="0" />
            <dynamics damping="0" friction="0" />
            <safety_controller soft_lower_limit="-3.0543" soft_upper_limit="3.0543" k_position="15"
                k_velocity="10" />
        </joint>

        <xacro:link_with_inertial name="${arm_id}_j2_link" xyz="-0.2125 -5.7643E-09 0.1346"
            rpy="0 0 0"
            mass="14.458"
            ixx="0.028392" ixy="-1.337E-07" ixz="-3.9895E-09" iyy="0.4559" iyz="4.214E-08"
            izz="0.44974"
            visual_mesh="package://frcobot_description/meshes/fr5v6/visual/j2_link.DAE"
            collision_mesh="package://frcobot_description/meshes/fr5v6/collision/j2_link.STL" />

        <joint name="${arm_id}_j2" type="revolute">
            <origin xyz="0 0 0.152" rpy="1.5708 0 0" />
            <parent link="${arm_id}_j1_link" />
            <child link="${arm_id}_j2_link" />
            <axis xyz="0 0 1" />
            <limit lower="-4.6251" upper="1.4835" effort="150" velocity="3.15" />
            <calibration rising="0" falling="0" />
            <dynamics damping="0" friction="0" />
            <safety_controller soft_lower_limit="-4.6251" soft_upper_limit="1.4835" k_position="15"
                k_velocity="10" />
        </joint>

        <xacro:link_with_inertial name="${arm_id}_j3_link" xyz="-0.18793 -8.4503E-07 0.0066357"
            rpy="0 0 0"
            mass="7.6737"
            ixx="0.0085096" ixy="2.1613E-06" ixz="-0.0068678" iyy="0.16971" iyz="3.7086E-08"
            izz="0.16854"
            visual_mesh="package://frcobot_description/meshes/fr5v6/visual/j3_link.DAE"
            collision_mesh="package://frcobot_description/meshes/fr5v6/collision/j3_link.STL" />

        <joint name="${arm_id}_j3" type="revolute">
            <origin xyz="-0.425 0 0" rpy="0 0 0" />
            <parent link="${arm_id}_j2_link" />
            <child link="${arm_id}_j3_link" />
            <axis xyz="0 0 1" />
            <limit lower="-2.8274" upper="2.8274" effort="150" velocity="3.15" />
            <calibration rising="0" falling="0" />
            <dynamics damping="0" friction="0" />
            <safety_controller soft_lower_limit="-2.8274" soft_upper_limit="2.8274" k_position="15"
                k_velocity="10" />
        </joint>

        <xacro:link_with_inertial name="${arm_id}_j4_link" xyz="4.98E-07 -0.003754 0.097155"
            rpy="0 0 0"
            mass="1.6266"
            ixx="0.00216" ixy="4.888E-09" ixz="3.1528E-08" iyy="0.0015455" iyz="3.7678E-05"
            izz="0.0019902"
            visual_mesh="package://frcobot_description/meshes/fr5v6/visual/j4_link.DAE"
            collision_mesh="package://frcobot_description/meshes/fr5v6/collision/j4_link.STL" />

        <joint name="${arm_id}_j4" type="revolute">
            <origin xyz="-0.39501 0 0" rpy="0 0 0" />
            <parent link="${arm_id}_j3_link" />
            <child link="${arm_id}_j4_link" />
            <axis xyz="0 0 1" />
            <limit lower="-4.6251" upper="1.4835" effort="28" velocity="3.2" />
            <calibration rising="0" falling="0" />
            <dynamics damping="0" friction="0" />
            <safety_controller soft_lower_limit="-4.6251" soft_upper_limit="1.4835" k_position="15"
                k_velocity="10" />
        </joint>

        <xacro:link_with_inertial name="${arm_id}_j5_link" xyz="-4.5588E-07 0.0038617 0.098257"
            rpy="0 0 0"
            mass="1.5812"
            ixx="0.0020612" ixy="8.7064E-09" ixz="-3.4742E-08" iyy="0.0014477" iyz="-2.8534E-05"
            izz="0.0019573"
            visual_mesh="package://frcobot_description/meshes/fr5v6/visual/j5_link.DAE"
            collision_mesh="package://frcobot_description/meshes/fr5v6/collision/j5_link.STL" />

        <joint name="${arm_id}_j5" type="revolute">
            <origin xyz="0 0 0.1021" rpy="1.5708 0 0" />
            <parent link="${arm_id}_j4_link" />
            <child link="${arm_id}_j5_link" />
            <axis xyz="0 0 1" />
            <limit lower="-3.0543" upper="3.0543" effort="28" velocity="3.2" />
            <calibration rising="0" falling="0" />
            <dynamics damping="0" friction="0" />
            <safety_controller soft_lower_limit="-3.0543" soft_upper_limit="3.0543" k_position="15"
                k_velocity="10" />
        </joint>

        <xacro:link_with_inertial name="${arm_id}_j6_link" xyz="7.7496E-05 1.7751E-05 0.076122"
            rpy="0 0 0"
            mass="0.52542"
            ixx="0.00027721" ixy="-1.8677E-09" ixz="-1.188E-07" iyy="0.00027839" iyz="2.2607E-07"
            izz="0.00041605"
            visual_mesh="package://frcobot_description/meshes/fr5v6/visual/j6_link.DAE"
            collision_mesh="package://frcobot_description/meshes/fr5v6/collision/j6_link.STL" />

        <joint name="${arm_id}_j6" type="revolute">
            <origin xyz="0 0 0.102" rpy="-1.5708 0 0" />
            <parent link="${arm_id}_j5_link" />
            <child link="${arm_id}_j6_link" />
            <axis xyz="0 0 1" />
            <limit lower="-3.0543" upper="3.0543" effort="28" velocity="3.2" />
            <calibration rising="0" falling="0" />
            <dynamics damping="0" friction="0" />
            <safety_controller soft_lower_limit="-3.0543" soft_upper_limit="3.0543" k_position="15"
                k_velocity="10" />
        </joint>


        <!-- Uncomment and modify the following section if you have a tool link -->

        <xacro:link_with_inertial name="${arm_id}_tool_link" xyz="0.24412 0.079181 -0.126"
            rpy="0 0 0"
            mass="0"
            ixx="0.10666" ixy="-0.046059" ixz="0.046354" iyy="0.87967" iyz="0.0095222" izz="0.85231"
            visual_mesh="package://frcobot_description/meshes/fr5v6/visual/toolA-250mm.DAE"
            collision_mesh="package://frcobot_description/meshes/fr5v6/collision/toolA-250mm.STL" 
            scale="0.001 0.001 0.001" />

        <joint name="${arm_id}_tool" type="fixed">
            <origin xyz="0 0 0.1" rpy="0 0 0" />
            <parent link="${arm_id}_j6_link" />
            <child link="${arm_id}_tool_link" />
            <axis xyz="0 0 1" />
            <limit lower="0" upper="0" effort="0" velocity="0" />
            <calibration rising="0" falling="0" />
            <dynamics damping="0" friction="0" />
            <safety_controller soft_lower_limit="0" soft_upper_limit="0" k_position="0"
                k_velocity="0" />
        </joint>

        <!-- 添加工具末端TCP坐标系（使用基本几何体） -->
        <link name="${arm_id}_tool_tcp_link">
            <inertial>
                <origin xyz="0 0 0" rpy="0 0 0" />
                <mass value="0.001" />
                <inertia ixx="0.0000001" ixy="0" ixz="0" iyy="0.0000001" iyz="0" izz="0.0000001" />
            </inertial>
            <visual>
                <origin xyz="0 0 0" rpy="0 0 0" />
                <geometry>
                    <sphere radius="0.005"/>
                </geometry>
                <material name="">
                    <color rgba="1 0 0 1" />
                </material>
            </visual>
            <!-- 添加碰撞几何体 -->
            <collision>
                <origin xyz="0 0 0" rpy="0 0 0" />
                <geometry>
                    <sphere radius="0.005"/>
                </geometry>
            </collision>
        </link>

        <joint name="${arm_id}_tool_tcp_joint" type="fixed">
            <origin xyz="0 0 0.25" rpy="0 0 0" />
            <parent link="${arm_id}_tool_link" />
            <child link="${arm_id}_tool_tcp_link" />
        </joint>

    </xacro:macro>

    <xacro:macro name="gazebo-joint" params="joint ">
        <transmission name="trans_${joint}">
            <type>transmission_interface/SimpleTransmission</type>
            <joint name="${joint}">
                <hardwareInterface>hardware_interface/PositionJointInterface</hardwareInterface>
            </joint>
            <actuator name="${joint}_motor">
                <hardwareInterface>hardware_interface/PositionJointInterface</hardwareInterface>
                <mechanicalReduction>1</mechanicalReduction>
            </actuator>
        </transmission>
    </xacro:macro>

</robot>